[2024-07-02T16:20:20.269+0000] {local_task_job_runner.py:120} INFO - ::group::Pre task execution logs
[2024-07-02T16:20:20.352+0000] {taskinstance.py:2076} INFO - Dependencies all met for dep_context=non-requeueable deps ti=<TaskInstance: pipeline_dag.extract_csv scheduled__2024-01-13T00:00:00+00:00 [queued]>
[2024-07-02T16:20:20.373+0000] {taskinstance.py:2076} INFO - Dependencies all met for dep_context=requeueable deps ti=<TaskInstance: pipeline_dag.extract_csv scheduled__2024-01-13T00:00:00+00:00 [queued]>
[2024-07-02T16:20:20.400+0000] {taskinstance.py:2306} INFO - Starting attempt 1 of 2
[2024-07-02T16:20:20.561+0000] {taskinstance.py:2330} INFO - Executing <Task(PythonOperator): extract_csv> on 2024-01-13 00:00:00+00:00
[2024-07-02T16:20:20.579+0000] {standard_task_runner.py:90} INFO - Running: ['airflow', 'tasks', 'run', 'pipeline_dag', 'extract_csv', 'scheduled__2024-01-13T00:00:00+00:00', '--job-id', '1630', '--raw', '--subdir', 'DAGS_FOLDER/dag_northwind.py', '--cfg-path', '/tmp/tmp5t6ozxvi']
[2024-07-02T16:20:20.587+0000] {standard_task_runner.py:91} INFO - Job 1630: Subtask extract_csv
[2024-07-02T16:20:20.596+0000] {logging_mixin.py:188} WARNING - /home/airflow/.local/lib/python3.12/site-packages/airflow/task/task_runner/standard_task_runner.py:61 DeprecationWarning: This process (pid=367) is multi-threaded, use of fork() may lead to deadlocks in the child.
[2024-07-02T16:20:20.597+0000] {standard_task_runner.py:63} INFO - Started process 380 to run task
[2024-07-02T16:20:20.688+0000] {task_command.py:426} INFO - Running <TaskInstance: pipeline_dag.extract_csv scheduled__2024-01-13T00:00:00+00:00 [running]> on host ee7e13960694
[2024-07-02T16:20:20.833+0000] {taskinstance.py:2648} INFO - Exporting env vars: AIRFLOW_CTX_DAG_OWNER='airflow' AIRFLOW_CTX_DAG_ID='pipeline_dag' AIRFLOW_CTX_TASK_ID='extract_csv' AIRFLOW_CTX_EXECUTION_DATE='2024-01-13T00:00:00+00:00' AIRFLOW_CTX_TRY_NUMBER='1' AIRFLOW_CTX_DAG_RUN_ID='scheduled__2024-01-13T00:00:00+00:00'
[2024-07-02T16:20:20.834+0000] {taskinstance.py:430} INFO - ::endgroup::
[2024-07-02T16:20:20.857+0000] {taskinstance.py:441} INFO - ::group::Post task execution logs
[2024-07-02T16:20:20.859+0000] {taskinstance.py:2905} ERROR - Task failed with exception
Traceback (most recent call last):
  File "/home/airflow/.local/lib/python3.12/site-packages/airflow/models/taskinstance.py", line 465, in _execute_task
    result = _execute_callable(context=context, **execute_callable_kwargs)
             ^^^^^^^^^^^^^^^^^^^^^^^^^^^^^^^^^^^^^^^^^^^^^^^^^^^^^^^^^^^^^
  File "/home/airflow/.local/lib/python3.12/site-packages/airflow/models/taskinstance.py", line 432, in _execute_callable
    return execute_callable(context=context, **execute_callable_kwargs)
           ^^^^^^^^^^^^^^^^^^^^^^^^^^^^^^^^^^^^^^^^^^^^^^^^^^^^^^^^^^^^
  File "/home/airflow/.local/lib/python3.12/site-packages/airflow/models/baseoperator.py", line 401, in wrapper
    return func(self, *args, **kwargs)
           ^^^^^^^^^^^^^^^^^^^^^^^^^^^
  File "/home/airflow/.local/lib/python3.12/site-packages/airflow/operators/python.py", line 235, in execute
    return_value = self.execute_callable()
                   ^^^^^^^^^^^^^^^^^^^^^^^
  File "/home/airflow/.local/lib/python3.12/site-packages/airflow/operators/python.py", line 252, in execute_callable
    return self.python_callable(*self.op_args, **self.op_kwargs)
           ^^^^^^^^^^^^^^^^^^^^^^^^^^^^^^^^^^^^^^^^^^^^^^^^^^^^^
  File "/opt/airflow/dags/dag_northwind.py", line 31, in extract_csv
    subprocess.run(extract_command, shell=True, check=True)
  File "/usr/local/lib/python3.12/subprocess.py", line 571, in run
    raise CalledProcessError(retcode, process.args,
subprocess.CalledProcessError: Command 'meltano elt tap-csv target-csv --transform=run' returned non-zero exit status 127.
[2024-07-02T16:20:20.885+0000] {taskinstance.py:1206} INFO - Marking task as UP_FOR_RETRY. dag_id=pipeline_dag, task_id=extract_csv, run_id=scheduled__2024-01-13T00:00:00+00:00, execution_date=20240113T000000, start_date=20240702T162020, end_date=20240702T162020
[2024-07-02T16:20:20.917+0000] {standard_task_runner.py:110} ERROR - Failed to execute job 1630 for task extract_csv (Command 'meltano elt tap-csv target-csv --transform=run' returned non-zero exit status 127.; 380)
[2024-07-02T16:20:20.974+0000] {local_task_job_runner.py:240} INFO - Task exited with return code 1
[2024-07-02T16:20:21.004+0000] {local_task_job_runner.py:222} INFO - ::endgroup::
[2024-07-03T16:17:56.173+0000] {local_task_job_runner.py:120} INFO - ::group::Pre task execution logs
[2024-07-03T16:17:56.257+0000] {taskinstance.py:2076} INFO - Dependencies all met for dep_context=non-requeueable deps ti=<TaskInstance: pipeline_dag.extract_csv scheduled__2024-01-13T00:00:00+00:00 [queued]>
[2024-07-03T16:17:56.280+0000] {taskinstance.py:2076} INFO - Dependencies all met for dep_context=requeueable deps ti=<TaskInstance: pipeline_dag.extract_csv scheduled__2024-01-13T00:00:00+00:00 [queued]>
[2024-07-03T16:17:56.281+0000] {taskinstance.py:2306} INFO - Starting attempt 1 of 2
[2024-07-03T16:17:56.317+0000] {taskinstance.py:2330} INFO - Executing <Task(PythonOperator): extract_csv> on 2024-01-13 00:00:00+00:00
[2024-07-03T16:17:56.334+0000] {logging_mixin.py:188} WARNING - /home/airflow/.local/lib/python3.12/site-packages/airflow/task/task_runner/standard_task_runner.py:61 DeprecationWarning: This process (pid=1456) is multi-threaded, use of fork() may lead to deadlocks in the child.
[2024-07-03T16:17:56.334+0000] {standard_task_runner.py:90} INFO - Running: ['airflow', 'tasks', 'run', 'pipeline_dag', 'extract_csv', 'scheduled__2024-01-13T00:00:00+00:00', '--job-id', '2379', '--raw', '--subdir', 'DAGS_FOLDER/northwind_dag_teste.py', '--cfg-path', '/tmp/tmp38az4ysq']
[2024-07-03T16:17:56.338+0000] {standard_task_runner.py:63} INFO - Started process 1465 to run task
[2024-07-03T16:17:56.340+0000] {standard_task_runner.py:91} INFO - Job 2379: Subtask extract_csv
[2024-07-03T16:17:56.467+0000] {task_command.py:426} INFO - Running <TaskInstance: pipeline_dag.extract_csv scheduled__2024-01-13T00:00:00+00:00 [running]> on host 3c2535f14011
[2024-07-03T16:17:56.717+0000] {taskinstance.py:2648} INFO - Exporting env vars: AIRFLOW_CTX_DAG_OWNER='airflow' AIRFLOW_CTX_DAG_ID='pipeline_dag' AIRFLOW_CTX_TASK_ID='extract_csv' AIRFLOW_CTX_EXECUTION_DATE='2024-01-13T00:00:00+00:00' AIRFLOW_CTX_TRY_NUMBER='1' AIRFLOW_CTX_DAG_RUN_ID='scheduled__2024-01-13T00:00:00+00:00'
[2024-07-03T16:17:56.722+0000] {taskinstance.py:430} INFO - ::endgroup::
[2024-07-03T16:17:56.784+0000] {logging_mixin.py:188} INFO - Command failed with error: Command 'meltano elt tap-csv target-csv --transform=run --job_id=extract_csv_2024-01-13' returned non-zero exit status 127.
[2024-07-03T16:17:56.785+0000] {taskinstance.py:441} INFO - ::group::Post task execution logs
[2024-07-03T16:17:56.786+0000] {taskinstance.py:2905} ERROR - Task failed with exception
Traceback (most recent call last):
  File "/home/airflow/.local/lib/python3.12/site-packages/airflow/models/taskinstance.py", line 465, in _execute_task
    result = _execute_callable(context=context, **execute_callable_kwargs)
             ^^^^^^^^^^^^^^^^^^^^^^^^^^^^^^^^^^^^^^^^^^^^^^^^^^^^^^^^^^^^^
  File "/home/airflow/.local/lib/python3.12/site-packages/airflow/models/taskinstance.py", line 432, in _execute_callable
    return execute_callable(context=context, **execute_callable_kwargs)
           ^^^^^^^^^^^^^^^^^^^^^^^^^^^^^^^^^^^^^^^^^^^^^^^^^^^^^^^^^^^^
  File "/home/airflow/.local/lib/python3.12/site-packages/airflow/models/baseoperator.py", line 401, in wrapper
    return func(self, *args, **kwargs)
           ^^^^^^^^^^^^^^^^^^^^^^^^^^^
  File "/home/airflow/.local/lib/python3.12/site-packages/airflow/operators/python.py", line 235, in execute
    return_value = self.execute_callable()
                   ^^^^^^^^^^^^^^^^^^^^^^^
  File "/home/airflow/.local/lib/python3.12/site-packages/airflow/operators/python.py", line 252, in execute_callable
    return self.python_callable(*self.op_args, **self.op_kwargs)
           ^^^^^^^^^^^^^^^^^^^^^^^^^^^^^^^^^^^^^^^^^^^^^^^^^^^^^
  File "/opt/airflow/dags/northwind_dag_teste.py", line 38, in extract_csv
    subprocess.run(extract_command, shell=True, check=True)
  File "/usr/local/lib/python3.12/subprocess.py", line 571, in run
    raise CalledProcessError(retcode, process.args,
subprocess.CalledProcessError: Command 'meltano elt tap-csv target-csv --transform=run --job_id=extract_csv_2024-01-13' returned non-zero exit status 127.
[2024-07-03T16:17:56.822+0000] {taskinstance.py:1206} INFO - Marking task as UP_FOR_RETRY. dag_id=pipeline_dag, task_id=extract_csv, run_id=scheduled__2024-01-13T00:00:00+00:00, execution_date=20240113T000000, start_date=20240703T161756, end_date=20240703T161756
[2024-07-03T16:17:56.858+0000] {standard_task_runner.py:110} ERROR - Failed to execute job 2379 for task extract_csv (Command 'meltano elt tap-csv target-csv --transform=run --job_id=extract_csv_2024-01-13' returned non-zero exit status 127.; 1465)
[2024-07-03T16:17:56.883+0000] {local_task_job_runner.py:240} INFO - Task exited with return code 1
[2024-07-03T16:17:56.902+0000] {local_task_job_runner.py:222} INFO - ::endgroup::
