[2024-07-13T00:05:03.740+0000] {local_task_job_runner.py:120} INFO - ::group::Pre task execution logs
[2024-07-13T00:05:03.825+0000] {taskinstance.py:2076} INFO - Dependencies all met for dep_context=non-requeueable deps ti=<TaskInstance: dag_pipeline_northwind.extract_postgres_category_id scheduled__2024-07-12T00:00:00+00:00 [queued]>
[2024-07-13T00:05:03.846+0000] {taskinstance.py:2076} INFO - Dependencies all met for dep_context=requeueable deps ti=<TaskInstance: dag_pipeline_northwind.extract_postgres_category_id scheduled__2024-07-12T00:00:00+00:00 [queued]>
[2024-07-13T00:05:03.848+0000] {taskinstance.py:2306} INFO - Starting attempt 2 of 2
[2024-07-13T00:05:03.892+0000] {taskinstance.py:2330} INFO - Executing <Task(PythonOperator): extract_postgres_category_id> on 2024-07-12 00:00:00+00:00
[2024-07-13T00:05:03.908+0000] {logging_mixin.py:188} WARNING - /home/airflow/.local/lib/python3.12/site-packages/airflow/task/task_runner/standard_task_runner.py:61 DeprecationWarning: This process (pid=3455) is multi-threaded, use of fork() may lead to deadlocks in the child.
[2024-07-13T00:05:03.910+0000] {standard_task_runner.py:63} INFO - Started process 3470 to run task
[2024-07-13T00:05:03.908+0000] {standard_task_runner.py:90} INFO - Running: ['airflow', 'tasks', 'run', 'dag_pipeline_northwind', 'extract_postgres_category_id', 'scheduled__2024-07-12T00:00:00+00:00', '--job-id', '5642', '--raw', '--subdir', 'DAGS_FOLDER/dag_pipeline_northwind.py', '--cfg-path', '/tmp/tmpniqiwqac']
[2024-07-13T00:05:03.912+0000] {standard_task_runner.py:91} INFO - Job 5642: Subtask extract_postgres_category_id
[2024-07-13T00:05:04.063+0000] {task_command.py:426} INFO - Running <TaskInstance: dag_pipeline_northwind.extract_postgres_category_id scheduled__2024-07-12T00:00:00+00:00 [running]> on host 5ef7300ef9b1
[2024-07-13T00:05:04.296+0000] {taskinstance.py:2648} INFO - Exporting env vars: AIRFLOW_CTX_DAG_OWNER='airflow' AIRFLOW_CTX_DAG_ID='dag_pipeline_northwind' AIRFLOW_CTX_TASK_ID='extract_postgres_category_id' AIRFLOW_CTX_EXECUTION_DATE='2024-07-12T00:00:00+00:00' AIRFLOW_CTX_TRY_NUMBER='2' AIRFLOW_CTX_DAG_RUN_ID='scheduled__2024-07-12T00:00:00+00:00'
[2024-07-13T00:05:04.297+0000] {taskinstance.py:430} INFO - ::endgroup::
[2024-07-13T00:05:04.328+0000] {logging_mixin.py:188} INFO - Running command: meltano elt tap-postgres target-csv --transform=run --job_id=extract_postgres_category_id_2024-07-12
[2024-07-13T00:05:04.332+0000] {logging_mixin.py:188} INFO - Command failed with error: Command 'meltano elt tap-postgres target-csv --transform=run --job_id=extract_postgres_category_id_2024-07-12' returned non-zero exit status 127.
[2024-07-13T00:05:04.333+0000] {taskinstance.py:441} INFO - ::group::Post task execution logs
[2024-07-13T00:05:04.334+0000] {taskinstance.py:2905} ERROR - Task failed with exception
Traceback (most recent call last):
  File "/home/airflow/.local/lib/python3.12/site-packages/airflow/models/taskinstance.py", line 465, in _execute_task
    result = _execute_callable(context=context, **execute_callable_kwargs)
             ^^^^^^^^^^^^^^^^^^^^^^^^^^^^^^^^^^^^^^^^^^^^^^^^^^^^^^^^^^^^^
  File "/home/airflow/.local/lib/python3.12/site-packages/airflow/models/taskinstance.py", line 432, in _execute_callable
    return execute_callable(context=context, **execute_callable_kwargs)
           ^^^^^^^^^^^^^^^^^^^^^^^^^^^^^^^^^^^^^^^^^^^^^^^^^^^^^^^^^^^^
  File "/home/airflow/.local/lib/python3.12/site-packages/airflow/models/baseoperator.py", line 401, in wrapper
    return func(self, *args, **kwargs)
           ^^^^^^^^^^^^^^^^^^^^^^^^^^^
  File "/home/airflow/.local/lib/python3.12/site-packages/airflow/operators/python.py", line 235, in execute
    return_value = self.execute_callable()
                   ^^^^^^^^^^^^^^^^^^^^^^^
  File "/home/airflow/.local/lib/python3.12/site-packages/airflow/operators/python.py", line 252, in execute_callable
    return self.python_callable(*self.op_args, **self.op_kwargs)
           ^^^^^^^^^^^^^^^^^^^^^^^^^^^^^^^^^^^^^^^^^^^^^^^^^^^^^
  File "/opt/airflow/dags/dag_pipeline_northwind.py", line 40, in extract_postgres_table
    result = subprocess.run(extract_command, shell=True, check=True, capture_output=True, text=True)
             ^^^^^^^^^^^^^^^^^^^^^^^^^^^^^^^^^^^^^^^^^^^^^^^^^^^^^^^^^^^^^^^^^^^^^^^^^^^^^^^^^^^^^^^
  File "/usr/local/lib/python3.12/subprocess.py", line 571, in run
    raise CalledProcessError(retcode, process.args,
subprocess.CalledProcessError: Command 'meltano elt tap-postgres target-csv --transform=run --job_id=extract_postgres_category_id_2024-07-12' returned non-zero exit status 127.
[2024-07-13T00:05:04.356+0000] {taskinstance.py:1206} INFO - Marking task as FAILED. dag_id=dag_pipeline_northwind, task_id=extract_postgres_category_id, run_id=scheduled__2024-07-12T00:00:00+00:00, execution_date=20240712T000000, start_date=20240713T000503, end_date=20240713T000504
[2024-07-13T00:05:04.395+0000] {standard_task_runner.py:110} ERROR - Failed to execute job 5642 for task extract_postgres_category_id (Command 'meltano elt tap-postgres target-csv --transform=run --job_id=extract_postgres_category_id_2024-07-12' returned non-zero exit status 127.; 3470)
[2024-07-13T00:05:04.420+0000] {local_task_job_runner.py:240} INFO - Task exited with return code 1
[2024-07-13T00:05:04.438+0000] {local_task_job_runner.py:222} INFO - ::endgroup::
[2024-07-14T21:53:01.671+0000] {local_task_job_runner.py:120} INFO - ::group::Pre task execution logs
[2024-07-14T21:53:01.907+0000] {taskinstance.py:2076} INFO - Dependencies all met for dep_context=non-requeueable deps ti=<TaskInstance: dag_pipeline_northwind.extract_postgres_category_id scheduled__2024-07-12T00:00:00+00:00 [queued]>
[2024-07-14T21:53:01.936+0000] {taskinstance.py:2076} INFO - Dependencies all met for dep_context=requeueable deps ti=<TaskInstance: dag_pipeline_northwind.extract_postgres_category_id scheduled__2024-07-12T00:00:00+00:00 [queued]>
[2024-07-14T21:53:01.939+0000] {taskinstance.py:2306} INFO - Starting attempt 2 of 2
[2024-07-14T21:53:02.020+0000] {taskinstance.py:2330} INFO - Executing <Task(PythonOperator): extract_postgres_category_id> on 2024-07-12 00:00:00+00:00
[2024-07-14T21:53:02.046+0000] {standard_task_runner.py:90} INFO - Running: ['airflow', 'tasks', 'run', 'dag_pipeline_northwind', 'extract_postgres_category_id', 'scheduled__2024-07-12T00:00:00+00:00', '--job-id', '5793', '--raw', '--subdir', 'DAGS_FOLDER/dag_pipeline_northwind.py', '--cfg-path', '/tmp/tmp7pgxs74e']
[2024-07-14T21:53:02.051+0000] {standard_task_runner.py:91} INFO - Job 5793: Subtask extract_postgres_category_id
[2024-07-14T21:53:02.143+0000] {logging_mixin.py:188} WARNING - /home/airflow/.local/lib/python3.12/site-packages/airflow/task/task_runner/standard_task_runner.py:61 DeprecationWarning: This process (pid=545) is multi-threaded, use of fork() may lead to deadlocks in the child.
[2024-07-14T21:53:02.147+0000] {standard_task_runner.py:63} INFO - Started process 569 to run task
[2024-07-14T21:53:02.296+0000] {task_command.py:426} INFO - Running <TaskInstance: dag_pipeline_northwind.extract_postgres_category_id scheduled__2024-07-12T00:00:00+00:00 [running]> on host ee4b7f7f7c3e
[2024-07-14T21:53:02.605+0000] {taskinstance.py:2648} INFO - Exporting env vars: AIRFLOW_CTX_DAG_OWNER='airflow' AIRFLOW_CTX_DAG_ID='dag_pipeline_northwind' AIRFLOW_CTX_TASK_ID='extract_postgres_category_id' AIRFLOW_CTX_EXECUTION_DATE='2024-07-12T00:00:00+00:00' AIRFLOW_CTX_TRY_NUMBER='2' AIRFLOW_CTX_DAG_RUN_ID='scheduled__2024-07-12T00:00:00+00:00'
[2024-07-14T21:53:02.609+0000] {taskinstance.py:430} INFO - ::endgroup::
[2024-07-14T21:53:02.653+0000] {logging_mixin.py:188} INFO - Running command: meltano elt tap-postgres target-csv --transform=run --job_id=extract_postgres_category_id_2024-07-12
[2024-07-14T21:53:02.666+0000] {logging_mixin.py:188} INFO - Command failed with error: Command 'meltano elt tap-postgres target-csv --transform=run --job_id=extract_postgres_category_id_2024-07-12' returned non-zero exit status 127.
[2024-07-14T21:53:02.667+0000] {taskinstance.py:441} INFO - ::group::Post task execution logs
[2024-07-14T21:53:02.668+0000] {taskinstance.py:2905} ERROR - Task failed with exception
Traceback (most recent call last):
  File "/home/airflow/.local/lib/python3.12/site-packages/airflow/models/taskinstance.py", line 465, in _execute_task
    result = _execute_callable(context=context, **execute_callable_kwargs)
             ^^^^^^^^^^^^^^^^^^^^^^^^^^^^^^^^^^^^^^^^^^^^^^^^^^^^^^^^^^^^^
  File "/home/airflow/.local/lib/python3.12/site-packages/airflow/models/taskinstance.py", line 432, in _execute_callable
    return execute_callable(context=context, **execute_callable_kwargs)
           ^^^^^^^^^^^^^^^^^^^^^^^^^^^^^^^^^^^^^^^^^^^^^^^^^^^^^^^^^^^^
  File "/home/airflow/.local/lib/python3.12/site-packages/airflow/models/baseoperator.py", line 401, in wrapper
    return func(self, *args, **kwargs)
           ^^^^^^^^^^^^^^^^^^^^^^^^^^^
  File "/home/airflow/.local/lib/python3.12/site-packages/airflow/operators/python.py", line 235, in execute
    return_value = self.execute_callable()
                   ^^^^^^^^^^^^^^^^^^^^^^^
  File "/home/airflow/.local/lib/python3.12/site-packages/airflow/operators/python.py", line 252, in execute_callable
    return self.python_callable(*self.op_args, **self.op_kwargs)
           ^^^^^^^^^^^^^^^^^^^^^^^^^^^^^^^^^^^^^^^^^^^^^^^^^^^^^
  File "/opt/airflow/dags/dag_pipeline_northwind.py", line 40, in extract_postgres_table
    result = subprocess.run(extract_command, shell=True, check=True, capture_output=True, text=True)
             ^^^^^^^^^^^^^^^^^^^^^^^^^^^^^^^^^^^^^^^^^^^^^^^^^^^^^^^^^^^^^^^^^^^^^^^^^^^^^^^^^^^^^^^
  File "/usr/local/lib/python3.12/subprocess.py", line 571, in run
    raise CalledProcessError(retcode, process.args,
subprocess.CalledProcessError: Command 'meltano elt tap-postgres target-csv --transform=run --job_id=extract_postgres_category_id_2024-07-12' returned non-zero exit status 127.
[2024-07-14T21:53:02.711+0000] {taskinstance.py:1206} INFO - Marking task as FAILED. dag_id=dag_pipeline_northwind, task_id=extract_postgres_category_id, run_id=scheduled__2024-07-12T00:00:00+00:00, execution_date=20240712T000000, start_date=20240714T215301, end_date=20240714T215302
[2024-07-14T21:53:02.785+0000] {standard_task_runner.py:110} ERROR - Failed to execute job 5793 for task extract_postgres_category_id (Command 'meltano elt tap-postgres target-csv --transform=run --job_id=extract_postgres_category_id_2024-07-12' returned non-zero exit status 127.; 569)
[2024-07-14T21:53:02.861+0000] {local_task_job_runner.py:240} INFO - Task exited with return code 1
[2024-07-14T21:53:02.949+0000] {taskinstance.py:3503} INFO - 0 downstream tasks scheduled from follow-on schedule check
[2024-07-14T21:53:02.953+0000] {local_task_job_runner.py:222} INFO - ::endgroup::
