[2024-06-30T21:03:36.808+0000] {local_task_job_runner.py:120} INFO - ::group::Pre task execution logs
[2024-06-30T21:03:36.866+0000] {taskinstance.py:2076} INFO - Dependencies all met for dep_context=non-requeueable deps ti=<TaskInstance: dag_northwind.extract_postgres scheduled__2024-01-17T00:00:00+00:00 [queued]>
[2024-06-30T21:03:36.879+0000] {taskinstance.py:2076} INFO - Dependencies all met for dep_context=requeueable deps ti=<TaskInstance: dag_northwind.extract_postgres scheduled__2024-01-17T00:00:00+00:00 [queued]>
[2024-06-30T21:03:36.880+0000] {taskinstance.py:2306} INFO - Starting attempt 2 of 2
[2024-06-30T21:03:37.057+0000] {taskinstance.py:2330} INFO - Executing <Task(BashOperator): extract_postgres> on 2024-01-17 00:00:00+00:00
[2024-06-30T21:03:37.066+0000] {standard_task_runner.py:90} INFO - Running: ['airflow', 'tasks', 'run', 'dag_northwind', 'extract_postgres', 'scheduled__2024-01-17T00:00:00+00:00', '--job-id', '439', '--raw', '--subdir', 'DAGS_FOLDER/dag_northwind.py', '--cfg-path', '/tmp/tmpknzu6sfz']
[2024-06-30T21:03:37.067+0000] {logging_mixin.py:188} WARNING - /home/airflow/.local/lib/python3.12/site-packages/airflow/task/task_runner/standard_task_runner.py:61 DeprecationWarning: This process (pid=860) is multi-threaded, use of fork() may lead to deadlocks in the child.
[2024-06-30T21:03:37.069+0000] {standard_task_runner.py:91} INFO - Job 439: Subtask extract_postgres
[2024-06-30T21:03:37.069+0000] {standard_task_runner.py:63} INFO - Started process 865 to run task
[2024-06-30T21:03:37.143+0000] {task_command.py:426} INFO - Running <TaskInstance: dag_northwind.extract_postgres scheduled__2024-01-17T00:00:00+00:00 [running]> on host a7d76f00647b
[2024-06-30T21:03:37.272+0000] {taskinstance.py:2648} INFO - Exporting env vars: AIRFLOW_CTX_DAG_OWNER='airflow' AIRFLOW_CTX_DAG_ID='dag_northwind' AIRFLOW_CTX_TASK_ID='extract_postgres' AIRFLOW_CTX_EXECUTION_DATE='2024-01-17T00:00:00+00:00' AIRFLOW_CTX_TRY_NUMBER='2' AIRFLOW_CTX_DAG_RUN_ID='scheduled__2024-01-17T00:00:00+00:00'
[2024-06-30T21:03:37.273+0000] {taskinstance.py:430} INFO - ::endgroup::
[2024-06-30T21:03:37.300+0000] {subprocess.py:63} INFO - Tmp dir root location: /tmp
[2024-06-30T21:03:37.301+0000] {subprocess.py:75} INFO - Running command: ['/usr/bin/bash', '-c', 'meltano elt tap-postgres target-csv --job_id=extract_postgres_2024-01-17 && mkdir -p /data/postgres/2024-01-17 && mv /project/output/tap-postgres/*.csv /data/postgres/2024-01-17/']
[2024-06-30T21:03:37.311+0000] {subprocess.py:86} INFO - Output:
[2024-06-30T21:03:37.313+0000] {subprocess.py:93} INFO - /usr/bin/bash: line 1: meltano: command not found
[2024-06-30T21:03:37.314+0000] {subprocess.py:97} INFO - Command exited with return code 127
[2024-06-30T21:03:37.315+0000] {taskinstance.py:441} INFO - ::group::Post task execution logs
[2024-06-30T21:03:37.328+0000] {taskinstance.py:2905} ERROR - Task failed with exception
Traceback (most recent call last):
  File "/home/airflow/.local/lib/python3.12/site-packages/airflow/models/taskinstance.py", line 465, in _execute_task
    result = _execute_callable(context=context, **execute_callable_kwargs)
             ^^^^^^^^^^^^^^^^^^^^^^^^^^^^^^^^^^^^^^^^^^^^^^^^^^^^^^^^^^^^^
  File "/home/airflow/.local/lib/python3.12/site-packages/airflow/models/taskinstance.py", line 432, in _execute_callable
    return execute_callable(context=context, **execute_callable_kwargs)
           ^^^^^^^^^^^^^^^^^^^^^^^^^^^^^^^^^^^^^^^^^^^^^^^^^^^^^^^^^^^^
  File "/home/airflow/.local/lib/python3.12/site-packages/airflow/models/baseoperator.py", line 401, in wrapper
    return func(self, *args, **kwargs)
           ^^^^^^^^^^^^^^^^^^^^^^^^^^^
  File "/home/airflow/.local/lib/python3.12/site-packages/airflow/operators/bash.py", line 243, in execute
    raise AirflowException(
airflow.exceptions.AirflowException: Bash command failed. The command returned a non-zero exit code 127.
[2024-06-30T21:03:37.337+0000] {taskinstance.py:1206} INFO - Marking task as FAILED. dag_id=dag_northwind, task_id=extract_postgres, run_id=scheduled__2024-01-17T00:00:00+00:00, execution_date=20240117T000000, start_date=20240630T210336, end_date=20240630T210337
[2024-06-30T21:03:37.370+0000] {standard_task_runner.py:110} ERROR - Failed to execute job 439 for task extract_postgres (Bash command failed. The command returned a non-zero exit code 127.; 865)
[2024-06-30T21:03:37.405+0000] {local_task_job_runner.py:240} INFO - Task exited with return code 1
[2024-06-30T21:03:37.427+0000] {local_task_job_runner.py:222} INFO - ::endgroup::
[2024-07-01T10:11:14.340+0000] {local_task_job_runner.py:120} INFO - ::group::Pre task execution logs
[2024-07-01T10:11:14.425+0000] {taskinstance.py:2076} INFO - Dependencies all met for dep_context=non-requeueable deps ti=<TaskInstance: dag_northwind.extract_postgres scheduled__2024-01-17T00:00:00+00:00 [queued]>
[2024-07-01T10:11:14.446+0000] {taskinstance.py:2076} INFO - Dependencies all met for dep_context=requeueable deps ti=<TaskInstance: dag_northwind.extract_postgres scheduled__2024-01-17T00:00:00+00:00 [queued]>
[2024-07-01T10:11:14.447+0000] {taskinstance.py:2306} INFO - Starting attempt 2 of 2
[2024-07-01T10:11:14.688+0000] {taskinstance.py:2330} INFO - Executing <Task(BashOperator): extract_postgres> on 2024-01-17 00:00:00+00:00
[2024-07-01T10:11:14.716+0000] {logging_mixin.py:188} WARNING - /home/airflow/.local/lib/python3.12/site-packages/airflow/task/task_runner/standard_task_runner.py:61 DeprecationWarning: This process (pid=5427) is multi-threaded, use of fork() may lead to deadlocks in the child.
[2024-07-01T10:11:14.716+0000] {standard_task_runner.py:90} INFO - Running: ['airflow', 'tasks', 'run', 'dag_northwind', 'extract_postgres', 'scheduled__2024-01-17T00:00:00+00:00', '--job-id', '973', '--raw', '--subdir', 'DAGS_FOLDER/dag_northwind.py', '--cfg-path', '/tmp/tmpb29kehxw']
[2024-07-01T10:11:14.721+0000] {standard_task_runner.py:91} INFO - Job 973: Subtask extract_postgres
[2024-07-01T10:11:14.719+0000] {standard_task_runner.py:63} INFO - Started process 5442 to run task
[2024-07-01T10:11:14.859+0000] {task_command.py:426} INFO - Running <TaskInstance: dag_northwind.extract_postgres scheduled__2024-01-17T00:00:00+00:00 [running]> on host 85c6ea7cd9cf
[2024-07-01T10:11:15.036+0000] {taskinstance.py:2648} INFO - Exporting env vars: AIRFLOW_CTX_DAG_OWNER='airflow' AIRFLOW_CTX_DAG_ID='dag_northwind' AIRFLOW_CTX_TASK_ID='extract_postgres' AIRFLOW_CTX_EXECUTION_DATE='2024-01-17T00:00:00+00:00' AIRFLOW_CTX_TRY_NUMBER='2' AIRFLOW_CTX_DAG_RUN_ID='scheduled__2024-01-17T00:00:00+00:00'
[2024-07-01T10:11:15.038+0000] {taskinstance.py:430} INFO - ::endgroup::
[2024-07-01T10:11:15.073+0000] {subprocess.py:63} INFO - Tmp dir root location: /tmp
[2024-07-01T10:11:15.075+0000] {subprocess.py:75} INFO - Running command: ['/usr/bin/bash', '-c', 'meltano elt tap-postgres target-csv --job_id=extract_postgres_2024-01-17 && mkdir -p /data/postgres/2024-01-17 && mv /project/output/tap-postgres/*.csv /data/postgres/2024-01-17/']
[2024-07-01T10:11:15.096+0000] {subprocess.py:86} INFO - Output:
[2024-07-01T10:11:15.117+0000] {subprocess.py:93} INFO - /usr/bin/bash: line 1: meltano: command not found
[2024-07-01T10:11:15.120+0000] {subprocess.py:97} INFO - Command exited with return code 127
[2024-07-01T10:11:15.122+0000] {taskinstance.py:441} INFO - ::group::Post task execution logs
[2024-07-01T10:11:15.156+0000] {taskinstance.py:2905} ERROR - Task failed with exception
Traceback (most recent call last):
  File "/home/airflow/.local/lib/python3.12/site-packages/airflow/models/taskinstance.py", line 465, in _execute_task
    result = _execute_callable(context=context, **execute_callable_kwargs)
             ^^^^^^^^^^^^^^^^^^^^^^^^^^^^^^^^^^^^^^^^^^^^^^^^^^^^^^^^^^^^^
  File "/home/airflow/.local/lib/python3.12/site-packages/airflow/models/taskinstance.py", line 432, in _execute_callable
    return execute_callable(context=context, **execute_callable_kwargs)
           ^^^^^^^^^^^^^^^^^^^^^^^^^^^^^^^^^^^^^^^^^^^^^^^^^^^^^^^^^^^^
  File "/home/airflow/.local/lib/python3.12/site-packages/airflow/models/baseoperator.py", line 401, in wrapper
    return func(self, *args, **kwargs)
           ^^^^^^^^^^^^^^^^^^^^^^^^^^^
  File "/home/airflow/.local/lib/python3.12/site-packages/airflow/operators/bash.py", line 243, in execute
    raise AirflowException(
airflow.exceptions.AirflowException: Bash command failed. The command returned a non-zero exit code 127.
[2024-07-01T10:11:15.167+0000] {taskinstance.py:1206} INFO - Marking task as FAILED. dag_id=dag_northwind, task_id=extract_postgres, run_id=scheduled__2024-01-17T00:00:00+00:00, execution_date=20240117T000000, start_date=20240701T101114, end_date=20240701T101115
[2024-07-01T10:11:15.473+0000] {standard_task_runner.py:110} ERROR - Failed to execute job 973 for task extract_postgres (Bash command failed. The command returned a non-zero exit code 127.; 5442)
[2024-07-01T10:11:15.512+0000] {local_task_job_runner.py:240} INFO - Task exited with return code 1
[2024-07-01T10:11:15.577+0000] {taskinstance.py:3503} INFO - 0 downstream tasks scheduled from follow-on schedule check
[2024-07-01T10:11:15.594+0000] {local_task_job_runner.py:222} INFO - ::endgroup::
