[2024-07-02T16:30:38.307+0000] {local_task_job_runner.py:120} INFO - ::group::Pre task execution logs
[2024-07-02T16:30:38.408+0000] {taskinstance.py:2076} INFO - Dependencies all met for dep_context=non-requeueable deps ti=<TaskInstance: pipeline_dag.extract_postgres scheduled__2024-01-30T00:00:00+00:00 [queued]>
[2024-07-02T16:30:38.436+0000] {taskinstance.py:2076} INFO - Dependencies all met for dep_context=requeueable deps ti=<TaskInstance: pipeline_dag.extract_postgres scheduled__2024-01-30T00:00:00+00:00 [queued]>
[2024-07-02T16:30:38.438+0000] {taskinstance.py:2306} INFO - Starting attempt 2 of 2
[2024-07-02T16:30:38.604+0000] {taskinstance.py:2330} INFO - Executing <Task(PythonOperator): extract_postgres> on 2024-01-30 00:00:00+00:00
[2024-07-02T16:30:38.618+0000] {logging_mixin.py:188} WARNING - /home/airflow/.local/lib/python3.12/site-packages/airflow/task/task_runner/standard_task_runner.py:61 DeprecationWarning: This process (pid=759) is multi-threaded, use of fork() may lead to deadlocks in the child.
[2024-07-02T16:30:38.620+0000] {standard_task_runner.py:63} INFO - Started process 776 to run task
[2024-07-02T16:30:38.618+0000] {standard_task_runner.py:90} INFO - Running: ['airflow', 'tasks', 'run', 'pipeline_dag', 'extract_postgres', 'scheduled__2024-01-30T00:00:00+00:00', '--job-id', '1727', '--raw', '--subdir', 'DAGS_FOLDER/dag_northwind.py', '--cfg-path', '/tmp/tmp6oixaro5']
[2024-07-02T16:30:38.623+0000] {standard_task_runner.py:91} INFO - Job 1727: Subtask extract_postgres
[2024-07-02T16:30:38.756+0000] {task_command.py:426} INFO - Running <TaskInstance: pipeline_dag.extract_postgres scheduled__2024-01-30T00:00:00+00:00 [running]> on host ee7e13960694
[2024-07-02T16:30:38.960+0000] {taskinstance.py:2648} INFO - Exporting env vars: AIRFLOW_CTX_DAG_OWNER='airflow' AIRFLOW_CTX_DAG_ID='pipeline_dag' AIRFLOW_CTX_TASK_ID='extract_postgres' AIRFLOW_CTX_EXECUTION_DATE='2024-01-30T00:00:00+00:00' AIRFLOW_CTX_TRY_NUMBER='2' AIRFLOW_CTX_DAG_RUN_ID='scheduled__2024-01-30T00:00:00+00:00'
[2024-07-02T16:30:38.963+0000] {taskinstance.py:430} INFO - ::endgroup::
[2024-07-02T16:30:38.995+0000] {taskinstance.py:441} INFO - ::group::Post task execution logs
[2024-07-02T16:30:38.997+0000] {taskinstance.py:2905} ERROR - Task failed with exception
Traceback (most recent call last):
  File "/home/airflow/.local/lib/python3.12/site-packages/airflow/models/taskinstance.py", line 465, in _execute_task
    result = _execute_callable(context=context, **execute_callable_kwargs)
             ^^^^^^^^^^^^^^^^^^^^^^^^^^^^^^^^^^^^^^^^^^^^^^^^^^^^^^^^^^^^^
  File "/home/airflow/.local/lib/python3.12/site-packages/airflow/models/taskinstance.py", line 432, in _execute_callable
    return execute_callable(context=context, **execute_callable_kwargs)
           ^^^^^^^^^^^^^^^^^^^^^^^^^^^^^^^^^^^^^^^^^^^^^^^^^^^^^^^^^^^^
  File "/home/airflow/.local/lib/python3.12/site-packages/airflow/models/baseoperator.py", line 401, in wrapper
    return func(self, *args, **kwargs)
           ^^^^^^^^^^^^^^^^^^^^^^^^^^^
  File "/home/airflow/.local/lib/python3.12/site-packages/airflow/operators/python.py", line 235, in execute
    return_value = self.execute_callable()
                   ^^^^^^^^^^^^^^^^^^^^^^^
  File "/home/airflow/.local/lib/python3.12/site-packages/airflow/operators/python.py", line 252, in execute_callable
    return self.python_callable(*self.op_args, **self.op_kwargs)
           ^^^^^^^^^^^^^^^^^^^^^^^^^^^^^^^^^^^^^^^^^^^^^^^^^^^^^
  File "/opt/airflow/dags/dag_northwind.py", line 27, in extract_postgres
    subprocess.run(extract_command, shell=True, check=True)
  File "/usr/local/lib/python3.12/subprocess.py", line 571, in run
    raise CalledProcessError(retcode, process.args,
subprocess.CalledProcessError: Command 'meltano elt tap-postgres target-csv --transform=run' returned non-zero exit status 127.
[2024-07-02T16:30:39.021+0000] {taskinstance.py:1206} INFO - Marking task as FAILED. dag_id=pipeline_dag, task_id=extract_postgres, run_id=scheduled__2024-01-30T00:00:00+00:00, execution_date=20240130T000000, start_date=20240702T163038, end_date=20240702T163039
[2024-07-02T16:30:39.044+0000] {standard_task_runner.py:110} ERROR - Failed to execute job 1727 for task extract_postgres (Command 'meltano elt tap-postgres target-csv --transform=run' returned non-zero exit status 127.; 776)
[2024-07-02T16:30:39.095+0000] {local_task_job_runner.py:240} INFO - Task exited with return code 1
[2024-07-02T16:30:39.146+0000] {taskinstance.py:3503} INFO - 0 downstream tasks scheduled from follow-on schedule check
[2024-07-02T16:30:39.154+0000] {local_task_job_runner.py:222} INFO - ::endgroup::
[2024-07-03T16:28:12.496+0000] {local_task_job_runner.py:120} INFO - ::group::Pre task execution logs
[2024-07-03T16:28:12.585+0000] {taskinstance.py:2076} INFO - Dependencies all met for dep_context=non-requeueable deps ti=<TaskInstance: pipeline_dag.extract_postgres scheduled__2024-01-30T00:00:00+00:00 [queued]>
[2024-07-03T16:28:12.608+0000] {taskinstance.py:2076} INFO - Dependencies all met for dep_context=requeueable deps ti=<TaskInstance: pipeline_dag.extract_postgres scheduled__2024-01-30T00:00:00+00:00 [queued]>
[2024-07-03T16:28:12.609+0000] {taskinstance.py:2306} INFO - Starting attempt 2 of 2
[2024-07-03T16:28:12.660+0000] {taskinstance.py:2330} INFO - Executing <Task(PythonOperator): extract_postgres> on 2024-01-30 00:00:00+00:00
[2024-07-03T16:28:12.675+0000] {logging_mixin.py:188} WARNING - /home/airflow/.local/lib/python3.12/site-packages/airflow/task/task_runner/standard_task_runner.py:61 DeprecationWarning: This process (pid=2001) is multi-threaded, use of fork() may lead to deadlocks in the child.
[2024-07-03T16:28:12.675+0000] {standard_task_runner.py:90} INFO - Running: ['airflow', 'tasks', 'run', 'pipeline_dag', 'extract_postgres', 'scheduled__2024-01-30T00:00:00+00:00', '--job-id', '2531', '--raw', '--subdir', 'DAGS_FOLDER/northwind_dag_teste.py', '--cfg-path', '/tmp/tmpqt5uk4hm']
[2024-07-03T16:28:12.679+0000] {standard_task_runner.py:63} INFO - Started process 2021 to run task
[2024-07-03T16:28:12.680+0000] {standard_task_runner.py:91} INFO - Job 2531: Subtask extract_postgres
[2024-07-03T16:28:12.793+0000] {task_command.py:426} INFO - Running <TaskInstance: pipeline_dag.extract_postgres scheduled__2024-01-30T00:00:00+00:00 [running]> on host 3c2535f14011
[2024-07-03T16:28:12.960+0000] {taskinstance.py:2648} INFO - Exporting env vars: AIRFLOW_CTX_DAG_OWNER='airflow' AIRFLOW_CTX_DAG_ID='pipeline_dag' AIRFLOW_CTX_TASK_ID='extract_postgres' AIRFLOW_CTX_EXECUTION_DATE='2024-01-30T00:00:00+00:00' AIRFLOW_CTX_TRY_NUMBER='2' AIRFLOW_CTX_DAG_RUN_ID='scheduled__2024-01-30T00:00:00+00:00'
[2024-07-03T16:28:12.961+0000] {taskinstance.py:430} INFO - ::endgroup::
[2024-07-03T16:28:12.992+0000] {logging_mixin.py:188} INFO - Command failed with error: Command 'meltano elt tap-postgres target-csv --transform=run --job_id=extract_postgres_2024-01-30' returned non-zero exit status 127.
[2024-07-03T16:28:12.994+0000] {taskinstance.py:441} INFO - ::group::Post task execution logs
[2024-07-03T16:28:12.995+0000] {taskinstance.py:2905} ERROR - Task failed with exception
Traceback (most recent call last):
  File "/home/airflow/.local/lib/python3.12/site-packages/airflow/models/taskinstance.py", line 465, in _execute_task
    result = _execute_callable(context=context, **execute_callable_kwargs)
             ^^^^^^^^^^^^^^^^^^^^^^^^^^^^^^^^^^^^^^^^^^^^^^^^^^^^^^^^^^^^^
  File "/home/airflow/.local/lib/python3.12/site-packages/airflow/models/taskinstance.py", line 432, in _execute_callable
    return execute_callable(context=context, **execute_callable_kwargs)
           ^^^^^^^^^^^^^^^^^^^^^^^^^^^^^^^^^^^^^^^^^^^^^^^^^^^^^^^^^^^^
  File "/home/airflow/.local/lib/python3.12/site-packages/airflow/models/baseoperator.py", line 401, in wrapper
    return func(self, *args, **kwargs)
           ^^^^^^^^^^^^^^^^^^^^^^^^^^^
  File "/home/airflow/.local/lib/python3.12/site-packages/airflow/operators/python.py", line 235, in execute
    return_value = self.execute_callable()
                   ^^^^^^^^^^^^^^^^^^^^^^^
  File "/home/airflow/.local/lib/python3.12/site-packages/airflow/operators/python.py", line 252, in execute_callable
    return self.python_callable(*self.op_args, **self.op_kwargs)
           ^^^^^^^^^^^^^^^^^^^^^^^^^^^^^^^^^^^^^^^^^^^^^^^^^^^^^
  File "/opt/airflow/dags/northwind_dag_teste.py", line 29, in extract_postgres
    subprocess.run(extract_command, shell=True, check=True)
  File "/usr/local/lib/python3.12/subprocess.py", line 571, in run
    raise CalledProcessError(retcode, process.args,
subprocess.CalledProcessError: Command 'meltano elt tap-postgres target-csv --transform=run --job_id=extract_postgres_2024-01-30' returned non-zero exit status 127.
[2024-07-03T16:28:13.015+0000] {taskinstance.py:1206} INFO - Marking task as FAILED. dag_id=pipeline_dag, task_id=extract_postgres, run_id=scheduled__2024-01-30T00:00:00+00:00, execution_date=20240130T000000, start_date=20240703T162812, end_date=20240703T162813
[2024-07-03T16:28:13.036+0000] {standard_task_runner.py:110} ERROR - Failed to execute job 2531 for task extract_postgres (Command 'meltano elt tap-postgres target-csv --transform=run --job_id=extract_postgres_2024-01-30' returned non-zero exit status 127.; 2021)
[2024-07-03T16:28:13.058+0000] {local_task_job_runner.py:240} INFO - Task exited with return code 1
[2024-07-03T16:28:13.087+0000] {taskinstance.py:3503} INFO - 0 downstream tasks scheduled from follow-on schedule check
[2024-07-03T16:28:13.090+0000] {local_task_job_runner.py:222} INFO - ::endgroup::
