[2024-07-12T18:16:57.447+0000] {local_task_job_runner.py:120} INFO - ::group::Pre task execution logs
[2024-07-12T18:16:57.593+0000] {taskinstance.py:2076} INFO - Dependencies all met for dep_context=non-requeueable deps ti=<TaskInstance: dag_pipeline_northwind.extract_postgres_territories scheduled__2024-07-10T00:00:00+00:00 [queued]>
[2024-07-12T18:16:57.617+0000] {taskinstance.py:2076} INFO - Dependencies all met for dep_context=requeueable deps ti=<TaskInstance: dag_pipeline_northwind.extract_postgres_territories scheduled__2024-07-10T00:00:00+00:00 [queued]>
[2024-07-12T18:16:57.618+0000] {taskinstance.py:2306} INFO - Starting attempt 2 of 2
[2024-07-12T18:16:57.784+0000] {taskinstance.py:2330} INFO - Executing <Task(PythonOperator): extract_postgres_territories> on 2024-07-10 00:00:00+00:00
[2024-07-12T18:16:57.804+0000] {standard_task_runner.py:90} INFO - Running: ['airflow', 'tasks', 'run', 'dag_pipeline_northwind', 'extract_postgres_territories', 'scheduled__2024-07-10T00:00:00+00:00', '--job-id', '5402', '--raw', '--subdir', 'DAGS_FOLDER/dag_pipeline_northwind.py', '--cfg-path', '/tmp/tmph9i4kqtu']
[2024-07-12T18:16:57.810+0000] {standard_task_runner.py:91} INFO - Job 5402: Subtask extract_postgres_territories
[2024-07-12T18:16:57.822+0000] {logging_mixin.py:188} WARNING - /home/airflow/.local/lib/python3.12/site-packages/airflow/task/task_runner/standard_task_runner.py:61 DeprecationWarning: This process (pid=218) is multi-threaded, use of fork() may lead to deadlocks in the child.
[2024-07-12T18:16:57.827+0000] {standard_task_runner.py:63} INFO - Started process 241 to run task
[2024-07-12T18:16:58.036+0000] {task_command.py:426} INFO - Running <TaskInstance: dag_pipeline_northwind.extract_postgres_territories scheduled__2024-07-10T00:00:00+00:00 [running]> on host ae84c7ea76bc
[2024-07-12T18:16:58.669+0000] {taskinstance.py:2648} INFO - Exporting env vars: AIRFLOW_CTX_DAG_OWNER='airflow' AIRFLOW_CTX_DAG_ID='dag_pipeline_northwind' AIRFLOW_CTX_TASK_ID='extract_postgres_territories' AIRFLOW_CTX_EXECUTION_DATE='2024-07-10T00:00:00+00:00' AIRFLOW_CTX_TRY_NUMBER='2' AIRFLOW_CTX_DAG_RUN_ID='scheduled__2024-07-10T00:00:00+00:00'
[2024-07-12T18:16:58.671+0000] {taskinstance.py:430} INFO - ::endgroup::
[2024-07-12T18:16:58.712+0000] {logging_mixin.py:188} INFO - Running command: meltano elt tap-postgres target-csv --transform=run --job_id=extract_postgres_territories_2024-07-10
[2024-07-12T18:16:58.717+0000] {logging_mixin.py:188} INFO - Command failed with error: Command 'meltano elt tap-postgres target-csv --transform=run --job_id=extract_postgres_territories_2024-07-10' returned non-zero exit status 127.
[2024-07-12T18:16:58.718+0000] {taskinstance.py:441} INFO - ::group::Post task execution logs
[2024-07-12T18:16:58.721+0000] {taskinstance.py:2905} ERROR - Task failed with exception
Traceback (most recent call last):
  File "/home/airflow/.local/lib/python3.12/site-packages/airflow/models/taskinstance.py", line 465, in _execute_task
    result = _execute_callable(context=context, **execute_callable_kwargs)
             ^^^^^^^^^^^^^^^^^^^^^^^^^^^^^^^^^^^^^^^^^^^^^^^^^^^^^^^^^^^^^
  File "/home/airflow/.local/lib/python3.12/site-packages/airflow/models/taskinstance.py", line 432, in _execute_callable
    return execute_callable(context=context, **execute_callable_kwargs)
           ^^^^^^^^^^^^^^^^^^^^^^^^^^^^^^^^^^^^^^^^^^^^^^^^^^^^^^^^^^^^
  File "/home/airflow/.local/lib/python3.12/site-packages/airflow/models/baseoperator.py", line 401, in wrapper
    return func(self, *args, **kwargs)
           ^^^^^^^^^^^^^^^^^^^^^^^^^^^
  File "/home/airflow/.local/lib/python3.12/site-packages/airflow/operators/python.py", line 235, in execute
    return_value = self.execute_callable()
                   ^^^^^^^^^^^^^^^^^^^^^^^
  File "/home/airflow/.local/lib/python3.12/site-packages/airflow/operators/python.py", line 252, in execute_callable
    return self.python_callable(*self.op_args, **self.op_kwargs)
           ^^^^^^^^^^^^^^^^^^^^^^^^^^^^^^^^^^^^^^^^^^^^^^^^^^^^^
  File "/opt/airflow/dags/dag_pipeline_northwind.py", line 40, in extract_postgres_table
    result = subprocess.run(extract_command, shell=True, check=True, capture_output=True, text=True)
             ^^^^^^^^^^^^^^^^^^^^^^^^^^^^^^^^^^^^^^^^^^^^^^^^^^^^^^^^^^^^^^^^^^^^^^^^^^^^^^^^^^^^^^^
  File "/usr/local/lib/python3.12/subprocess.py", line 571, in run
    raise CalledProcessError(retcode, process.args,
subprocess.CalledProcessError: Command 'meltano elt tap-postgres target-csv --transform=run --job_id=extract_postgres_territories_2024-07-10' returned non-zero exit status 127.
[2024-07-12T18:16:58.748+0000] {taskinstance.py:1206} INFO - Marking task as FAILED. dag_id=dag_pipeline_northwind, task_id=extract_postgres_territories, run_id=scheduled__2024-07-10T00:00:00+00:00, execution_date=20240710T000000, start_date=20240712T181657, end_date=20240712T181658
[2024-07-12T18:16:58.854+0000] {standard_task_runner.py:110} ERROR - Failed to execute job 5402 for task extract_postgres_territories (Command 'meltano elt tap-postgres target-csv --transform=run --job_id=extract_postgres_territories_2024-07-10' returned non-zero exit status 127.; 241)
[2024-07-12T18:16:58.863+0000] {local_task_job_runner.py:240} INFO - Task exited with return code 1
[2024-07-12T18:16:58.876+0000] {local_task_job_runner.py:222} INFO - ::endgroup::
[2024-07-12T18:36:55.831+0000] {local_task_job_runner.py:120} INFO - ::group::Pre task execution logs
[2024-07-12T18:36:55.957+0000] {taskinstance.py:2076} INFO - Dependencies all met for dep_context=non-requeueable deps ti=<TaskInstance: dag_pipeline_northwind.extract_postgres_territories scheduled__2024-07-10T00:00:00+00:00 [queued]>
[2024-07-12T18:36:55.987+0000] {taskinstance.py:2076} INFO - Dependencies all met for dep_context=requeueable deps ti=<TaskInstance: dag_pipeline_northwind.extract_postgres_territories scheduled__2024-07-10T00:00:00+00:00 [queued]>
[2024-07-12T18:36:55.991+0000] {taskinstance.py:2306} INFO - Starting attempt 2 of 2
[2024-07-12T18:36:56.055+0000] {taskinstance.py:2330} INFO - Executing <Task(PythonOperator): extract_postgres_territories> on 2024-07-10 00:00:00+00:00
[2024-07-12T18:36:56.094+0000] {standard_task_runner.py:90} INFO - Running: ['airflow', 'tasks', 'run', 'dag_pipeline_northwind', 'extract_postgres_territories', 'scheduled__2024-07-10T00:00:00+00:00', '--job-id', '5493', '--raw', '--subdir', 'DAGS_FOLDER/dag_pipeline_northwind.py', '--cfg-path', '/tmp/tmp7th02vff']
[2024-07-12T18:36:56.114+0000] {standard_task_runner.py:91} INFO - Job 5493: Subtask extract_postgres_territories
[2024-07-12T18:36:56.103+0000] {logging_mixin.py:188} WARNING - /home/airflow/.local/lib/python3.12/site-packages/airflow/task/task_runner/standard_task_runner.py:61 DeprecationWarning: This process (pid=459) is multi-threaded, use of fork() may lead to deadlocks in the child.
[2024-07-12T18:36:56.120+0000] {standard_task_runner.py:63} INFO - Started process 476 to run task
[2024-07-12T18:36:56.314+0000] {task_command.py:426} INFO - Running <TaskInstance: dag_pipeline_northwind.extract_postgres_territories scheduled__2024-07-10T00:00:00+00:00 [running]> on host da29552222cb
[2024-07-12T18:36:56.595+0000] {taskinstance.py:2648} INFO - Exporting env vars: AIRFLOW_CTX_DAG_OWNER='airflow' AIRFLOW_CTX_DAG_ID='dag_pipeline_northwind' AIRFLOW_CTX_TASK_ID='extract_postgres_territories' AIRFLOW_CTX_EXECUTION_DATE='2024-07-10T00:00:00+00:00' AIRFLOW_CTX_TRY_NUMBER='2' AIRFLOW_CTX_DAG_RUN_ID='scheduled__2024-07-10T00:00:00+00:00'
[2024-07-12T18:36:56.599+0000] {taskinstance.py:430} INFO - ::endgroup::
[2024-07-12T18:36:56.637+0000] {logging_mixin.py:188} INFO - Running command: meltano elt tap-postgres target-csv --transform=run --job_id=extract_postgres_territories_2024-07-10
[2024-07-12T18:36:56.677+0000] {logging_mixin.py:188} INFO - Command failed with error: Command 'meltano elt tap-postgres target-csv --transform=run --job_id=extract_postgres_territories_2024-07-10' returned non-zero exit status 127.
[2024-07-12T18:36:56.678+0000] {taskinstance.py:441} INFO - ::group::Post task execution logs
[2024-07-12T18:36:56.679+0000] {taskinstance.py:2905} ERROR - Task failed with exception
Traceback (most recent call last):
  File "/home/airflow/.local/lib/python3.12/site-packages/airflow/models/taskinstance.py", line 465, in _execute_task
    result = _execute_callable(context=context, **execute_callable_kwargs)
             ^^^^^^^^^^^^^^^^^^^^^^^^^^^^^^^^^^^^^^^^^^^^^^^^^^^^^^^^^^^^^
  File "/home/airflow/.local/lib/python3.12/site-packages/airflow/models/taskinstance.py", line 432, in _execute_callable
    return execute_callable(context=context, **execute_callable_kwargs)
           ^^^^^^^^^^^^^^^^^^^^^^^^^^^^^^^^^^^^^^^^^^^^^^^^^^^^^^^^^^^^
  File "/home/airflow/.local/lib/python3.12/site-packages/airflow/models/baseoperator.py", line 401, in wrapper
    return func(self, *args, **kwargs)
           ^^^^^^^^^^^^^^^^^^^^^^^^^^^
  File "/home/airflow/.local/lib/python3.12/site-packages/airflow/operators/python.py", line 235, in execute
    return_value = self.execute_callable()
                   ^^^^^^^^^^^^^^^^^^^^^^^
  File "/home/airflow/.local/lib/python3.12/site-packages/airflow/operators/python.py", line 252, in execute_callable
    return self.python_callable(*self.op_args, **self.op_kwargs)
           ^^^^^^^^^^^^^^^^^^^^^^^^^^^^^^^^^^^^^^^^^^^^^^^^^^^^^
  File "/opt/airflow/dags/dag_pipeline_northwind.py", line 40, in extract_postgres_table
    result = subprocess.run(extract_command, shell=True, check=True, capture_output=True, text=True)
             ^^^^^^^^^^^^^^^^^^^^^^^^^^^^^^^^^^^^^^^^^^^^^^^^^^^^^^^^^^^^^^^^^^^^^^^^^^^^^^^^^^^^^^^
  File "/usr/local/lib/python3.12/subprocess.py", line 571, in run
    raise CalledProcessError(retcode, process.args,
subprocess.CalledProcessError: Command 'meltano elt tap-postgres target-csv --transform=run --job_id=extract_postgres_territories_2024-07-10' returned non-zero exit status 127.
[2024-07-12T18:36:56.714+0000] {taskinstance.py:1206} INFO - Marking task as FAILED. dag_id=dag_pipeline_northwind, task_id=extract_postgres_territories, run_id=scheduled__2024-07-10T00:00:00+00:00, execution_date=20240710T000000, start_date=20240712T183655, end_date=20240712T183656
[2024-07-12T18:36:56.739+0000] {standard_task_runner.py:110} ERROR - Failed to execute job 5493 for task extract_postgres_territories (Command 'meltano elt tap-postgres target-csv --transform=run --job_id=extract_postgres_territories_2024-07-10' returned non-zero exit status 127.; 476)
[2024-07-12T18:36:56.784+0000] {local_task_job_runner.py:240} INFO - Task exited with return code 1
[2024-07-12T18:36:56.816+0000] {local_task_job_runner.py:222} INFO - ::endgroup::
[2024-07-12T19:09:27.906+0000] {local_task_job_runner.py:120} INFO - ::group::Pre task execution logs
[2024-07-12T19:09:28.090+0000] {taskinstance.py:2076} INFO - Dependencies all met for dep_context=non-requeueable deps ti=<TaskInstance: dag_pipeline_northwind.extract_postgres_territories scheduled__2024-07-10T00:00:00+00:00 [queued]>
[2024-07-12T19:09:28.119+0000] {taskinstance.py:2076} INFO - Dependencies all met for dep_context=requeueable deps ti=<TaskInstance: dag_pipeline_northwind.extract_postgres_territories scheduled__2024-07-10T00:00:00+00:00 [queued]>
[2024-07-12T19:09:28.124+0000] {taskinstance.py:2306} INFO - Starting attempt 2 of 2
[2024-07-12T19:09:28.482+0000] {taskinstance.py:2330} INFO - Executing <Task(PythonOperator): extract_postgres_territories> on 2024-07-10 00:00:00+00:00
[2024-07-12T19:09:28.537+0000] {standard_task_runner.py:90} INFO - Running: ['airflow', 'tasks', 'run', 'dag_pipeline_northwind', 'extract_postgres_territories', 'scheduled__2024-07-10T00:00:00+00:00', '--job-id', '5595', '--raw', '--subdir', 'DAGS_FOLDER/dag_pipeline_northwind.py', '--cfg-path', '/tmp/tmpbbpkk450']
[2024-07-12T19:09:28.532+0000] {logging_mixin.py:188} WARNING - /home/airflow/.local/lib/python3.12/site-packages/airflow/task/task_runner/standard_task_runner.py:61 DeprecationWarning: This process (pid=411) is multi-threaded, use of fork() may lead to deadlocks in the child.
[2024-07-12T19:09:28.551+0000] {standard_task_runner.py:91} INFO - Job 5595: Subtask extract_postgres_territories
[2024-07-12T19:09:28.567+0000] {standard_task_runner.py:63} INFO - Started process 437 to run task
[2024-07-12T19:09:28.839+0000] {task_command.py:426} INFO - Running <TaskInstance: dag_pipeline_northwind.extract_postgres_territories scheduled__2024-07-10T00:00:00+00:00 [running]> on host 5ef7300ef9b1
[2024-07-12T19:09:29.378+0000] {taskinstance.py:2648} INFO - Exporting env vars: AIRFLOW_CTX_DAG_OWNER='airflow' AIRFLOW_CTX_DAG_ID='dag_pipeline_northwind' AIRFLOW_CTX_TASK_ID='extract_postgres_territories' AIRFLOW_CTX_EXECUTION_DATE='2024-07-10T00:00:00+00:00' AIRFLOW_CTX_TRY_NUMBER='2' AIRFLOW_CTX_DAG_RUN_ID='scheduled__2024-07-10T00:00:00+00:00'
[2024-07-12T19:09:29.390+0000] {taskinstance.py:430} INFO - ::endgroup::
[2024-07-12T19:09:29.459+0000] {logging_mixin.py:188} INFO - Running command: meltano elt tap-postgres target-csv --transform=run --job_id=extract_postgres_territories_2024-07-10
[2024-07-12T19:09:29.489+0000] {logging_mixin.py:188} INFO - Command failed with error: Command 'meltano elt tap-postgres target-csv --transform=run --job_id=extract_postgres_territories_2024-07-10' returned non-zero exit status 127.
[2024-07-12T19:09:29.502+0000] {taskinstance.py:441} INFO - ::group::Post task execution logs
[2024-07-12T19:09:29.516+0000] {taskinstance.py:2905} ERROR - Task failed with exception
Traceback (most recent call last):
  File "/home/airflow/.local/lib/python3.12/site-packages/airflow/models/taskinstance.py", line 465, in _execute_task
    result = _execute_callable(context=context, **execute_callable_kwargs)
             ^^^^^^^^^^^^^^^^^^^^^^^^^^^^^^^^^^^^^^^^^^^^^^^^^^^^^^^^^^^^^
  File "/home/airflow/.local/lib/python3.12/site-packages/airflow/models/taskinstance.py", line 432, in _execute_callable
    return execute_callable(context=context, **execute_callable_kwargs)
           ^^^^^^^^^^^^^^^^^^^^^^^^^^^^^^^^^^^^^^^^^^^^^^^^^^^^^^^^^^^^
  File "/home/airflow/.local/lib/python3.12/site-packages/airflow/models/baseoperator.py", line 401, in wrapper
    return func(self, *args, **kwargs)
           ^^^^^^^^^^^^^^^^^^^^^^^^^^^
  File "/home/airflow/.local/lib/python3.12/site-packages/airflow/operators/python.py", line 235, in execute
    return_value = self.execute_callable()
                   ^^^^^^^^^^^^^^^^^^^^^^^
  File "/home/airflow/.local/lib/python3.12/site-packages/airflow/operators/python.py", line 252, in execute_callable
    return self.python_callable(*self.op_args, **self.op_kwargs)
           ^^^^^^^^^^^^^^^^^^^^^^^^^^^^^^^^^^^^^^^^^^^^^^^^^^^^^
  File "/opt/airflow/dags/dag_pipeline_northwind.py", line 40, in extract_postgres_table
    result = subprocess.run(extract_command, shell=True, check=True, capture_output=True, text=True)
             ^^^^^^^^^^^^^^^^^^^^^^^^^^^^^^^^^^^^^^^^^^^^^^^^^^^^^^^^^^^^^^^^^^^^^^^^^^^^^^^^^^^^^^^
  File "/usr/local/lib/python3.12/subprocess.py", line 571, in run
    raise CalledProcessError(retcode, process.args,
subprocess.CalledProcessError: Command 'meltano elt tap-postgres target-csv --transform=run --job_id=extract_postgres_territories_2024-07-10' returned non-zero exit status 127.
[2024-07-12T19:09:29.577+0000] {taskinstance.py:1206} INFO - Marking task as FAILED. dag_id=dag_pipeline_northwind, task_id=extract_postgres_territories, run_id=scheduled__2024-07-10T00:00:00+00:00, execution_date=20240710T000000, start_date=20240712T190928, end_date=20240712T190929
[2024-07-12T19:09:29.664+0000] {standard_task_runner.py:110} ERROR - Failed to execute job 5595 for task extract_postgres_territories (Command 'meltano elt tap-postgres target-csv --transform=run --job_id=extract_postgres_territories_2024-07-10' returned non-zero exit status 127.; 437)
[2024-07-12T19:09:29.718+0000] {local_task_job_runner.py:240} INFO - Task exited with return code 1
[2024-07-12T19:09:29.802+0000] {taskinstance.py:3503} INFO - 0 downstream tasks scheduled from follow-on schedule check
[2024-07-12T19:09:29.805+0000] {local_task_job_runner.py:222} INFO - ::endgroup::
[2024-07-14T21:52:58.458+0000] {local_task_job_runner.py:120} INFO - ::group::Pre task execution logs
[2024-07-14T21:52:58.646+0000] {taskinstance.py:2076} INFO - Dependencies all met for dep_context=non-requeueable deps ti=<TaskInstance: dag_pipeline_northwind.extract_postgres_territories scheduled__2024-07-10T00:00:00+00:00 [queued]>
[2024-07-14T21:52:58.678+0000] {taskinstance.py:2076} INFO - Dependencies all met for dep_context=requeueable deps ti=<TaskInstance: dag_pipeline_northwind.extract_postgres_territories scheduled__2024-07-10T00:00:00+00:00 [queued]>
[2024-07-14T21:52:58.680+0000] {taskinstance.py:2306} INFO - Starting attempt 2 of 2
[2024-07-14T21:52:58.751+0000] {taskinstance.py:2330} INFO - Executing <Task(PythonOperator): extract_postgres_territories> on 2024-07-10 00:00:00+00:00
[2024-07-14T21:52:58.796+0000] {logging_mixin.py:188} WARNING - /home/airflow/.local/lib/python3.12/site-packages/airflow/task/task_runner/standard_task_runner.py:61 DeprecationWarning: This process (pid=497) is multi-threaded, use of fork() may lead to deadlocks in the child.
[2024-07-14T21:52:58.805+0000] {standard_task_runner.py:63} INFO - Started process 511 to run task
[2024-07-14T21:52:58.815+0000] {standard_task_runner.py:90} INFO - Running: ['airflow', 'tasks', 'run', 'dag_pipeline_northwind', 'extract_postgres_territories', 'scheduled__2024-07-10T00:00:00+00:00', '--job-id', '5773', '--raw', '--subdir', 'DAGS_FOLDER/dag_pipeline_northwind.py', '--cfg-path', '/tmp/tmpncqnx1zg']
[2024-07-14T21:52:58.828+0000] {standard_task_runner.py:91} INFO - Job 5773: Subtask extract_postgres_territories
[2024-07-14T21:52:59.038+0000] {task_command.py:426} INFO - Running <TaskInstance: dag_pipeline_northwind.extract_postgres_territories scheduled__2024-07-10T00:00:00+00:00 [running]> on host ee4b7f7f7c3e
[2024-07-14T21:52:59.366+0000] {taskinstance.py:2648} INFO - Exporting env vars: AIRFLOW_CTX_DAG_OWNER='airflow' AIRFLOW_CTX_DAG_ID='dag_pipeline_northwind' AIRFLOW_CTX_TASK_ID='extract_postgres_territories' AIRFLOW_CTX_EXECUTION_DATE='2024-07-10T00:00:00+00:00' AIRFLOW_CTX_TRY_NUMBER='2' AIRFLOW_CTX_DAG_RUN_ID='scheduled__2024-07-10T00:00:00+00:00'
[2024-07-14T21:52:59.376+0000] {taskinstance.py:430} INFO - ::endgroup::
[2024-07-14T21:52:59.451+0000] {logging_mixin.py:188} INFO - Running command: meltano elt tap-postgres target-csv --transform=run --job_id=extract_postgres_territories_2024-07-10
[2024-07-14T21:52:59.487+0000] {logging_mixin.py:188} INFO - Command failed with error: Command 'meltano elt tap-postgres target-csv --transform=run --job_id=extract_postgres_territories_2024-07-10' returned non-zero exit status 127.
[2024-07-14T21:52:59.493+0000] {taskinstance.py:441} INFO - ::group::Post task execution logs
[2024-07-14T21:52:59.495+0000] {taskinstance.py:2905} ERROR - Task failed with exception
Traceback (most recent call last):
  File "/home/airflow/.local/lib/python3.12/site-packages/airflow/models/taskinstance.py", line 465, in _execute_task
    result = _execute_callable(context=context, **execute_callable_kwargs)
             ^^^^^^^^^^^^^^^^^^^^^^^^^^^^^^^^^^^^^^^^^^^^^^^^^^^^^^^^^^^^^
  File "/home/airflow/.local/lib/python3.12/site-packages/airflow/models/taskinstance.py", line 432, in _execute_callable
    return execute_callable(context=context, **execute_callable_kwargs)
           ^^^^^^^^^^^^^^^^^^^^^^^^^^^^^^^^^^^^^^^^^^^^^^^^^^^^^^^^^^^^
  File "/home/airflow/.local/lib/python3.12/site-packages/airflow/models/baseoperator.py", line 401, in wrapper
    return func(self, *args, **kwargs)
           ^^^^^^^^^^^^^^^^^^^^^^^^^^^
  File "/home/airflow/.local/lib/python3.12/site-packages/airflow/operators/python.py", line 235, in execute
    return_value = self.execute_callable()
                   ^^^^^^^^^^^^^^^^^^^^^^^
  File "/home/airflow/.local/lib/python3.12/site-packages/airflow/operators/python.py", line 252, in execute_callable
    return self.python_callable(*self.op_args, **self.op_kwargs)
           ^^^^^^^^^^^^^^^^^^^^^^^^^^^^^^^^^^^^^^^^^^^^^^^^^^^^^
  File "/opt/airflow/dags/dag_pipeline_northwind.py", line 40, in extract_postgres_table
    result = subprocess.run(extract_command, shell=True, check=True, capture_output=True, text=True)
             ^^^^^^^^^^^^^^^^^^^^^^^^^^^^^^^^^^^^^^^^^^^^^^^^^^^^^^^^^^^^^^^^^^^^^^^^^^^^^^^^^^^^^^^
  File "/usr/local/lib/python3.12/subprocess.py", line 571, in run
    raise CalledProcessError(retcode, process.args,
subprocess.CalledProcessError: Command 'meltano elt tap-postgres target-csv --transform=run --job_id=extract_postgres_territories_2024-07-10' returned non-zero exit status 127.
[2024-07-14T21:52:59.580+0000] {taskinstance.py:1206} INFO - Marking task as FAILED. dag_id=dag_pipeline_northwind, task_id=extract_postgres_territories, run_id=scheduled__2024-07-10T00:00:00+00:00, execution_date=20240710T000000, start_date=20240714T215258, end_date=20240714T215259
[2024-07-14T21:52:59.665+0000] {standard_task_runner.py:110} ERROR - Failed to execute job 5773 for task extract_postgres_territories (Command 'meltano elt tap-postgres target-csv --transform=run --job_id=extract_postgres_territories_2024-07-10' returned non-zero exit status 127.; 511)
[2024-07-14T21:52:59.688+0000] {local_task_job_runner.py:240} INFO - Task exited with return code 1
[2024-07-14T21:52:59.708+0000] {local_task_job_runner.py:222} INFO - ::endgroup::
